<?xml version="1.0" encoding="utf-8"?>
<!-- This URDF was automatically created by SolidWorks to URDF Exporter! Originally created by Stephen Brawner (brawner@gmail.com) 
     Commit Version: 1.6.0-1-g15f4949  Build Version: 1.6.7594.29634
     For more information, please see http://wiki.ros.org/sw_urdf_exporter -->
<robot xmlns:xacro="http://www.ros.org/wiki/xacro" name="arm">
<xacro:macro 
    name="dual_arm" params="connected_to:='' xyz:='0 0 0' rpy:='0 0 0' " >
  <link
    name="base_link">
    <inertial>
      <origin
        xyz="-1.0447 -0.13029 -0.28463"
        rpy="0 0 0" />
      <mass
        value="61.679" />
      <inertia
        ixx="0.30023"
        ixy="-1.5703E-05"
        ixz="-0.0035756"
        iyy="10.999"
        iyz="-0.0001023"
        izz="11.091" />
    </inertial>
    <visual>
      <origin
        xyz="0 0 0"
        rpy="0 0 0" />
      <geometry>
        <mesh
          filename="package://dual_arm/meshes/base_link.STL" />
      </geometry>
      <material
        name="">
        <color
          rgba="0.79216 0.81961 0.93333 1" />
      </material>
    </visual>
    <collision>
      <origin
        xyz="0 0 0"
        rpy="0 0 0" />
      <geometry>
        <mesh
          filename="package://dual_arm/meshes/base_link.STL" />
      </geometry>
    </collision>
  </link>
  <link
    name="right_1_link">
    <inertial>
      <origin
        xyz="-0.00098956 -0.0041921 -0.35366"
        rpy="0 0 0" />
      <mass
        value="9.8697" />
      <inertia
        ixx="0.43325"
        ixy="2.3126E-09"
        ixz="-3.9044E-07"
        iyy="0.43707"
        iyz="-0.0010121"
        izz="0.01889" />
    </inertial>
    <visual>
      <origin
        xyz="0 0 0"
        rpy="0 0 0" />
      <geometry>
        <mesh
          filename="package://dual_arm/meshes/right_1_link.STL" />
      </geometry>
      <material
        name="">
        <color
          rgba="1 1 1 1" />
      </material>
    </visual>
    <collision>
      <origin
        xyz="0 0 0"
        rpy="0 0 0" />
      <geometry>
        <mesh
          filename="package://dual_arm/meshes/right_1_link.STL" />
      </geometry>
    </collision>
  </link>
  <joint
    name="right_base_1_joint"
    type="prismatic">
    <origin
      xyz="-1.7875 -0.0875 0.079"
      rpy="3.1416 0 1.5708" />
    <parent
      link="base_link" />
    <child
      link="right_1_link" />
    <axis
      xyz="0 1 0" />
    <limit
      lower="0"
      upper="0.65"
      effort="300"
      velocity="1" />
  </joint>
  <link
    name="right_2_link">
    <inertial>
      <origin
        xyz="-0.00096005 0.013986 -0.28925"
        rpy="0 0 0" />
      <mass
        value="3.9719" />
      <inertia
        ixx="0.13532"
        ixy="2.0338E-09"
        ixz="-2.0413E-09"
        iyy="0.13727"
        iyz="-0.00040347"
        izz="0.0040386" />
    </inertial>
    <visual>
      <origin
        xyz="0 0 0"
        rpy="0 0 0" />
      <geometry>
        <mesh
          filename="package://dual_arm/meshes/right_2_link.STL" />
      </geometry>
      <material
        name="">
        <color
          rgba="1 1 1 1" />
      </material>
    </visual>
    <collision>
      <origin
        xyz="0 0 0"
        rpy="0 0 0" />
      <geometry>
        <mesh
          filename="package://dual_arm/meshes/right_2_link.STL" />
      </geometry>
    </collision>
  </link>
  <joint
    name="right_1_2_joint"
    type="prismatic">
    <origin
      xyz="0.098 -0.0985 -0.107"
      rpy="3.1416 -1.5708 0" />
    <parent
      link="right_1_link" />
    <child
      link="right_2_link" />
    <axis
      xyz="1 0 0 "/>
    <limit
      lower="-0.65"
      upper="0"
      effort="300"
      velocity="1" />
  </joint>
  <link
    name="right_3_link">
    <inertial>
      <origin
        xyz="0.00364150157313201 0.00914664907061941 -0.0107895838042573"
        rpy="0 0 0" />
      <mass
        value="0.719267154702061" />
      <inertia
        ixx="0.000805348023951252"
        ixy="-5.16567651983959E-06"
        ixz="-6.55472814689721E-06"
        iyy="0.000797167920254832"
        iyz="5.2655277764295E-06"
        izz="0.00151458012475229" />
    </inertial>
    <visual>
      <origin
        xyz="0 0 0"
        rpy="0 0 0" />
      <geometry>
        <mesh
          filename="package://dual_arm/meshes/right_3_link.STL" />
      </geometry>
      <material
        name="">
        <color
          rgba="1 1 1 1" />
      </material>
    </visual>
    <collision>
      <origin
        xyz="0 0 0"
        rpy="0 0 0" />
      <geometry>
        <mesh
          filename="package://dual_arm/meshes/right_3_link.STL" />
      </geometry>
    </collision>
  </link>
  <joint
    name="right_2_3_joint"
    type="prismatic">
    <origin
      xyz="0 0.0685 -0.14503"
      rpy="1.5708 -1.5708 0" />
    <parent
      link="right_2_link" />
    <child
      link="right_3_link" />
    <axis
      xyz="1 0 0" />
    <limit
      lower="-0.45"
      upper="0"
      effort="300"
      velocity="1" />
  </joint>
  <link
    name="right_4_link">
    <inertial>
      <origin
        xyz="-0.0126766104477603 0.00278828853347443 0.358381368288642"
        rpy="0 0 0" />
      <mass
        value="0.650868387593756" />
      <inertia
        ixx="0.0334986354360226"
        ixy="7.70486376562764E-22"
        ixz="-3.34128630325317E-21"
        iyy="0.0334751243882282"
        iyz="-0.000260194887458867"
        izz="3.40532339622394E-05" />
    </inertial>
    <visual>
      <origin
        xyz="0 0 0"
        rpy="0 0 0" />
      <geometry>
        <mesh
          filename="package://dual_arm/meshes/right_4_link.STL" />
      </geometry>
      <material
        name="">
        <color
          rgba="0.792156862745098 0.819607843137255 0.933333333333333 1" />
      </material>
    </visual>
    <collision>
      <origin
        xyz="0 0 0"
        rpy="0 0 0" />
      <geometry>
        <mesh
          filename="package://dual_arm/meshes/right_4_link.STL" />
      </geometry>
    </collision>
  </link>
  <joint
    name="right_3_4_joint"
    type="revolute">
    <origin
      xyz="-0.0075 -0.01 -0.044"
      rpy="3.1416 -1.5708 3.1416" />
    <parent
      link="right_3_link" />
    <child
      link="right_4_link" />
    <axis
      xyz="1 0 0" />
    <limit
      lower="-0.7854"
      upper="0.7854"
      effort="100"
      velocity="3.14159" />
  </joint>
  <link name="right_gripper">
    <visual>
      <origin xyz="0.0 0.0 0.0" rpy="0.0 0.0 0.0"/>
      <geometry>
        <sphere radius="0.0005"/>
      </geometry>
      <material name="">
        <color rgba="0.0 0.0 0.0 1.0"/>
      </material>
    </visual>
  </link>
  <joint name="right_grpper_joint" type="fixed">
    <origin xyz="0.0 0.0 0.8" rpy="0.0 0.0 0.0"/>
    <parent link="right_4_link"/>
    <child link="right_gripper"/>
    <axis xyz="0.0 0.0 0.0"/>
    <limit lower="0.0" upper="0.0" effort="0.0" velocity="0.0"/>
  </joint>
  <link
    name="left_1_link">
    <inertial>
      <origin
        xyz="0.00394495618424638 -0.00421512053030085 0.538159430486452"
        rpy="0 0 0" />
      <mass
        value="9.87893377391119" />
      <inertia
        ixx="0.433248773327187"
        ixy="1.84061601485323E-07"
        ixz="-3.90282110795032E-07"
        iyy="0.43707398465744"
        iyz="-0.00101213255528186"
        izz="0.0188902708758529" />
    </inertial>
    <visual>
      <origin
        xyz="0 0 0"
        rpy="0 0 0" />
      <geometry>
        <mesh
          filename="package://dual_arm/meshes/left_1_link.STL" />
      </geometry>
      <material
        name="">
        <color
          rgba="1 1 1 1" />
      </material>
    </visual>
    <collision>
      <origin
        xyz="0 0 0"
        rpy="0 0 0" />
      <geometry>
        <mesh
          filename="package://dual_arm/meshes/left_1_link.STL" />
      </geometry>
    </collision>
  </link>
  <joint
    name="left_base_1_joint"
    type="prismatic">
    <origin
      xyz="-0.1825 -0.073362 0.971"
      rpy="3.1416 0 -1.5708" />
    <parent
      link="base_link" />
    <child
      link="left_1_link" />
    <axis
      xyz="0 1 0" />
    <limit
      lower="0"
      upper="0.65"
      effort="300"
      velocity="1" />
    <!-- <mimic
      joint="right_base_1_joint"
      multiplier="1"
      offset="0" /> -->
  </joint>
  <link
    name="left_2_link">
    <inertial>
      <origin
        xyz="-7.34858074391553E-09 0.0146261059723333 -0.293624874307354"
        rpy="0 0 0" />
      <mass
        value="3.74345447306113" />
      <inertia
        ixx="0.13288058609288"
        ixy="4.16287065982165E-10"
        ixz="-2.16796975195158E-09"
        iyy="0.134749250946563"
        iyz="-0.00040162545432782"
        izz="0.00386350980301212" />
    </inertial>
    <visual>
      <origin
        xyz="0 0 0"
        rpy="0 0 0" />
      <geometry>
        <mesh
          filename="package://dual_arm/meshes/left_2_link.STL" />
      </geometry>
      <material
        name="">
        <color
          rgba="1 1 1 1" />
      </material>
    </visual>
    <collision>
      <origin
        xyz="0 0 0"
        rpy="0 0 0" />
      <geometry>
        <mesh
          filename="package://dual_arm/meshes/left_2_link.STL" />
      </geometry>
    </collision>
  </link>
  <joint
    name="left_1_2_joint"
    type="prismatic">
    <origin
      xyz="-0.083862 -0.0985 0.7723"
      rpy="3.1416 1.5708 0" />
    <parent
      link="left_1_link" />
    <child
      link="left_2_link" />
    <axis
      xyz="1 0 0" />
    <limit
      lower="0"
      upper="0.65"
      effort="300"
      velocity="1" />
  </joint>
  <link
    name="left_3_link">
    <inertial>
      <origin
        xyz="-0.00169872005765292 -0.0274279533168932 -0.00596041619574236"
        rpy="0 0 0" />
      <mass
        value="0.719267154702076" />
      <inertia
        ixx="0.000797167920254836"
        ixy="-5.16567651984819E-06"
        ixz="-5.26552777642979E-06"
        iyy="0.000805348023951288"
        iyz="6.55472814689708E-06"
        izz="0.00151458012475233" />
    </inertial>
    <visual>
      <origin
        xyz="0 0 0"
        rpy="0 0 0" />
      <geometry>
        <mesh
          filename="package://dual_arm/meshes/left_3_link.STL" />
      </geometry>
      <material
        name="">
        <color
          rgba="1 1 1 1" />
      </material>
    </visual>
    <collision>
      <origin
        xyz="0 0 0"
        rpy="0 0 0" />
      <geometry>
        <mesh
          filename="package://dual_arm/meshes/left_3_link.STL" />
      </geometry>
    </collision>
  </link>
  <joint
    name="left_2_3_joint"
    type="prismatic">
    <origin
      xyz="-0.0018547 0.08525 -0.176"
      rpy="-1.5708 0 0" />
    <parent
      link="left_2_link" />
    <child
      link="left_3_link" />
    <axis
      xyz="0 1 0" />
    <limit
      lower="0"
      upper="0.45"
      effort="300"
      velocity="1" />
  </joint>
      <link name="left_4_link">
      <inertial>
      <origin
        xyz="-0.00169872005765292 -0.0274279533168932 -0.00596041619574236"
        rpy="0 0 0" />
      <mass
        value="0.719267154702076" />
      <inertia
        ixx="0.000797167920254836"
        ixy="-5.16567651984819E-06"
        ixz="-5.26552777642979E-06"
        iyy="0.000805348023951288"
        iyz="6.55472814689708E-06"
        izz="0.00151458012475233" />
    </inertial>
      <visual>
          <origin
        xyz="0 0.35 0"
        rpy="0 0 0" />
        <!-- the mesh origin is at front plate in between the two infrared camera axes -->
        <geometry>
          <box size="0.01 0.8 0.02 "/>
        </geometry>
        <material name="" >
          <color rgba="0.792156862745098 0.819607843137255 0.933333333333333 1"/>
        </material>
      </visual>
      <collision>
          <origin
        xyz="0 0.35 0"
        rpy="0 0 0" />
        <geometry>
         <box size="0.01 0.8 0.02 "/>
        </geometry>
      </collision>
    </link>
  <joint
    name="left_3_4_joint"
    type="revolute">
    <origin
      xyz="-0.020845 -0.038618 0.02725"
      rpy="0 -1.5708 0" />
    <parent
      link="left_3_link" />
    <child
      link="left_4_link" />
    <axis
      xyz="1 0 0" />
    <limit
      lower="-0.7854"
      upper="0.7854"
      effort="100"
      velocity="3.14159" />
  </joint>
  <link name="left_gripper">
    <visual>
      <origin xyz="0.0 0.0 0.0" rpy="0.0 0.0 0.0"/>
      <geometry>
        <sphere radius="0.0005"/>
      </geometry>
      <material name="">
        <color rgba="0.0 0.0 0.0 1.0"/>
      </material>
    </visual>
  </link>
  <joint name="left_grpper_joint" type="fixed">
    <origin xyz="0.0 0.8 0.0" rpy="0.0 0.0 0.0"/>
    <parent link="left_4_link"/>
    <child link="left_gripper"/>
    <axis xyz="0.0 0.0 0.0"/>
    <limit lower="0.0" upper="0.0" effort="0.0" velocity="0.0"/>
  </joint>
  <link name="stick">
    <visual>
      <origin xyz="0.0 0.0 0.0" rpy="0.0 0.0 0.0"/>
      <geometry>
        <box size="0.02 0.02 1.0"/>
      </geometry>
      <material name="">
        <color rgba="0.8 0.8 0.8 1.0"/>
      </material>
    </visual>
  </link>
  <joint name="stick_joint" type="fixed">
    <origin xyz="-1.05 0.13 0.4" rpy="0.0 0.0 0.0"/>
    <parent link="base_link"/>
    <child link="stick"/>
    <axis xyz="0.0 0.0 0.0"/>
    <limit lower="0.0" upper="0.0" effort="0.0" velocity="0.0"/>
  </joint>
</xacro:macro>
</robot>